<?xml version="1.0" ?>
<!-- =================================================================================== -->
<!-- |    This document was autogenerated by xacro from my_robot_description/urdf/lz_gripper_body.urdf.xacro | -->
<!-- |    EDITING THIS FILE BY HAND IS NOT RECOMMENDED                                 | -->
<!-- =================================================================================== -->
<robot name="lz_gripper">
  <link name="base_link">
    <inertial>
      <origin rpy="0 0 0" xyz="-0.0094603 -0.088524 0.0020382"/>
      <mass value="0.37668"/>
      <inertia ixx="0.00026243" ixy="-4.7759E-06" ixz="-3.6528E-06" iyy="0.00031103" iyz="1.2051E-05" izz="0.00042537"/>
    </inertial>
    <visual>
      <origin rpy="0 0 0" xyz="0 0 0"/>
      <geometry>
        <mesh filename="./lz_gripper/meshes/base_link.STL"/>
      </geometry>
      <material name="">
        <color rgba="0.89804 0.92157 0.92941 1"/>
      </material>
    </visual>
    <collision>
      <origin rpy="0 0 0" xyz="0 0 0"/>
      <geometry>
        <mesh filename="./lz_gripper/meshes/base_link.STL"/>
      </geometry>
    </collision>
  </link>
  <link name="thumb_link1">
    <inertial>
      <origin rpy="0 0 0" xyz="-0.00017965 6.8304E-06 0.018159"/>
      <mass value="0.0099033"/>
      <inertia ixx="6.2516E-07" ixy="-5.4183E-09" ixz="6.2081E-08" iyy="1.0583E-06" iyz="3.9831E-09" izz="6.1988E-07"/>
    </inertial>
    <visual>
      <origin rpy="0 0 0" xyz="0 0 0"/>
      <geometry>
        <mesh filename="./lz_gripper/meshes/thumb_link1.STL"/>
      </geometry>
      <material name="">
        <color rgba="0.89804 0.92157 0.92941 1"/>
      </material>
    </visual>
    <collision>
      <origin rpy="0 0 0" xyz="0 0 0"/>
      <geometry>
        <mesh filename="./lz_gripper/meshes/thumb_link1.STL"/>
      </geometry>
    </collision>
  </link>
  <joint name="thumb_joint1" type="revolute">
    <origin rpy="3.1416 0 -3.1416" xyz="0.023 -0.0245 -0.04835"/>
    <parent link="base_link"/>
    <child link="thumb_link1"/>
    <axis xyz="0 0 1"/>
    <limit effort="100" lower="0" upper="2.14" velocity="1"/>
  </joint>
  <link name="thumb_link2">
    <inertial>
      <origin rpy="0 0 0" xyz="-0.020501 0.0067015 -0.0064038"/>
      <mass value="0.014226"/>
      <inertia ixx="6.8248E-07" ixy="6.3443E-07" ixz="4.2546E-10" iyy="2.4065E-06" iyz="5.4467E-10" izz="2.8832E-06"/>
    </inertial>
    <visual>
      <origin rpy="0 0 0" xyz="0 0 0"/>
      <geometry>
        <mesh filename="./lz_gripper/meshes/thumb_link2.STL"/>
      </geometry>
      <material name="">
        <color rgba="0.89804 0.92157 0.92941 1"/>
      </material>
    </visual>
    <collision>
      <origin rpy="0 0 0" xyz="0 0 0"/>
      <geometry>
        <mesh filename="./lz_gripper/meshes/thumb_link2.STL"/>
      </geometry>
    </collision>
  </link>
  <joint name="thumb_joint2" type="revolute">
    <origin rpy="-1.5708 0 0.018038" xyz="-0.0088613 0.0060912 0.01565"/>
    <parent link="thumb_link1"/>
    <child link="thumb_link2"/>
    <axis xyz="0 0 -1"/>
    <limit effort="100" lower="0" upper="0.35" velocity="1"/>
  </joint>
  <link name="thumb_link3">
    <inertial>
      <origin rpy="0 0 0" xyz="-0.0196680927954652 -0.0005819719341843 0.00789994316554879"/>
      <mass value="0.00784968038272673"/>
      <inertia ixx="2.81075874673003E-07" ixy="1.75602810939405E-08" ixz="-8.67190758135838E-12" iyy="1.53707272171153E-06" iyz="8.14073757746129E-13" izz="1.36361714001957E-06"/>
    </inertial>
    <visual>
      <origin rpy="0 0 0" xyz="0 0 0"/>
      <geometry>
        <mesh filename="./lz_gripper/meshes/thumb_link3.STL"/>
      </geometry>
      <material name="">
        <color rgba="0.898039215686275 0.92156862745098 0.929411764705882 1"/>
      </material>
    </visual>
    <collision>
      <origin rpy="0 0 0" xyz="0 0 0"/>
      <geometry>
        <mesh filename="./lz_gripper/meshes/thumb_link3.STL"/>
      </geometry>
    </collision>
  </link>
  <joint name="thumb_joint3" type="revolute">
    <origin rpy="0 0 -0.34907" xyz="-0.042286 0.015391 -0.01415"/>
    <parent link="thumb_link2"/>
    <child link="thumb_link3"/>
    <axis xyz="0 0 -1"/>
    <limit effort="100" lower="0" upper="1.57" velocity="1"/>
  </joint>
  <link name="index_link1">
    <inertial>
      <origin rpy="0 0 0" xyz="-0.0215644823473152 0.000393824084923317 -0.00874621135392779"/>
      <mass value="0.0142262329639115"/>
      <inertia ixx="4.74796817289846E-07" ixy="3.63252054246068E-08" ixz="-2.22673309099261E-10" iyy="2.61422515976766E-06" iyz="6.54075662009712E-10" izz="2.88324671047069E-06"/>
    </inertial>
    <visual>
      <origin rpy="0 0 0" xyz="0 0 0"/>
      <geometry>
        <mesh filename="./lz_gripper/meshes/index_link1.STL"/>
      </geometry>
      <material name="">
        <color rgba="0.898039215686275 0.92156862745098 0.929411764705882 1"/>
      </material>
    </visual>
    <collision>
      <origin rpy="0 0 0" xyz="0 0 0"/>
      <geometry>
        <mesh filename="./lz_gripper/meshes/index_link1.STL"/>
      </geometry>
    </collision>
  </link>
  <joint name="index_joint1" type="revolute">
    <origin rpy="3.1416 1.5359 3.1416" xyz="0.031418 0 -0.0053197"/>
    <parent link="base_link"/>
    <child link="index_link1"/>
    <axis xyz="0 0 1"/>
    <limit effort="100" lower="0" upper="1.57" velocity="1"/>
  </joint>
  <link name="index_link2">
    <inertial>
      <origin rpy="0 0 0" xyz="-0.019676 -6.2395E-05 -0.0079"/>
      <mass value="0.0078496"/>
      <inertia ixx="2.8357E-07" ixy="-5.8625E-08" ixz="5.9491E-12" iyy="1.5346E-06" iyz="6.753E-14" izz="1.3636E-06"/>
    </inertial>
    <visual>
      <origin rpy="0 0 0" xyz="0 0 0"/>
      <geometry>
        <mesh filename="./lz_gripper/meshes/index_link2.STL"/>
      </geometry>
      <material name="">
        <color rgba="0.89804 0.92157 0.92941 1"/>
      </material>
    </visual>
    <collision>
      <origin rpy="0 0 0" xyz="0 0 0"/>
      <geometry>
        <mesh filename="./lz_gripper/meshes/index_link2.STL"/>
      </geometry>
    </collision>
  </link>
  <joint name="index_joint2" type="revolute">
    <origin rpy="0 0 0" xyz="-0.044995 -0.00066876 -0.001"/>
    <parent link="index_link1"/>
    <child link="index_link2"/>
    <axis xyz="0 0 1"/>
    <limit effort="100" lower="0" upper="1.57" velocity="1"/>
  </joint>
  <link name="middle_link1">
    <inertial>
      <origin rpy="0 0 0" xyz="-0.0215562506031045 0.000714276767812562 -0.00874619886653837"/>
      <mass value="0.0142262397904175"/>
      <inertia ixx="4.76348437272591E-07" ixy="6.81026341965301E-08" ixz="-2.11739551609207E-10" iyy="2.61267178108045E-06" iyz="6.56674816237693E-10" izz="2.88324556739897E-06"/>
    </inertial>
    <visual>
      <origin rpy="0 0 0" xyz="0 0 0"/>
      <geometry>
        <mesh filename="./lz_gripper/meshes/middle_link1.STL"/>
      </geometry>
      <material name="">
        <color rgba="0.898039215686275 0.92156862745098 0.929411764705882 1"/>
      </material>
    </visual>
    <collision>
      <origin rpy="0 0 0" xyz="0 0 0"/>
      <geometry>
        <mesh filename="./lz_gripper/meshes/middle_link1.STL"/>
      </geometry>
    </collision>
  </link>
  <joint name="middle_joint1" type="revolute">
    <origin rpy="0 1.5708 0" xyz="0.0089 0 0"/>
    <parent link="base_link"/>
    <child link="middle_link1"/>
    <axis xyz="0 0 1"/>
    <limit effort="100" lower="0" upper="1.57" velocity="1"/>
  </joint>
  <link name="middle_link2">
    <inertial>
      <origin rpy="0 0 0" xyz="-0.0196680995356125 0.000581962591357868 -0.00789993606542237"/>
      <mass value="0.00784967565480307"/>
      <inertia ixx="2.81075990649539E-07" ixy="-1.75598147871464E-08" ixz="9.1619521816691E-12" iyy="1.53707336727064E-06" iyz="9.30781747045291E-13" izz="1.36361817821565E-06"/>
    </inertial>
    <visual>
      <origin rpy="0 0 0" xyz="0 0 0"/>
      <geometry>
        <mesh filename="./lz_gripper/meshes/middle_link2.STL"/>
      </geometry>
      <material name="">
        <color rgba="0.898039215686275 0.92156862745098 0.929411764705882 1"/>
      </material>
    </visual>
    <collision>
      <origin rpy="0 0 0" xyz="0 0 0"/>
      <geometry>
        <mesh filename="./lz_gripper/meshes/middle_link2.STL"/>
      </geometry>
    </collision>
  </link>
  <joint name="middle_joint2" type="revolute">
    <origin rpy="0 0 1.5708" xyz="-0.045 0 -0.001"/>
    <parent link="middle_link1"/>
    <child link="middle_link2"/>
    <axis xyz="0 0 1"/>
    <limit effort="100" lower="0" upper="1.57" velocity="1"/>
  </joint>
  <link name="ring_link1">
    <inertial>
      <origin rpy="0 0 0" xyz="-0.0215562631632659 0.00071427737556939 -0.00874620018386888"/>
      <mass value="0.0142262435769468"/>
      <inertia ixx="4.76349000995179E-07" ixy="6.81020931307809E-08" ixz="-2.12503697751352E-10" iyy="2.61267824583491E-06" iyz="6.56558908193673E-10" izz="2.88325223980858E-06"/>
    </inertial>
    <visual>
      <origin rpy="0 0 0" xyz="0 0 0"/>
      <geometry>
        <mesh filename="./lz_gripper/meshes/ring_link1.STL"/>
      </geometry>
      <material name="">
        <color rgba="0.898039215686275 0.92156862745098 0.929411764705882 1"/>
      </material>
    </visual>
    <collision>
      <origin rpy="0 0 0" xyz="0 0 0"/>
      <geometry>
        <mesh filename="./lz_gripper/meshes/ring_link1.STL"/>
      </geometry>
    </collision>
  </link>
  <joint name="ring_joint1" type="revolute">
    <origin rpy="0 1.5359 0" xyz="-0.013629 0 -0.0046985"/>
    <parent link="base_link"/>
    <child link="ring_link1"/>
    <axis xyz="0 0 1"/>
    <limit effort="100" lower="0" upper="1.57" velocity="1"/>
  </joint>
  <link name="ring_link2">
    <inertial>
      <origin rpy="0 0 0" xyz="-0.0196679867849359 0.000581976188691607 -0.00789991025971003"/>
      <mass value="0.00784962520464454"/>
      <inertia ixx="2.81074318951396E-07" ixy="-1.7555732490274E-08" ixz="1.27085169733249E-11" iyy="1.5370525534456E-06" iyz="2.09501544213668E-12" izz="1.36359734443304E-06"/>
    </inertial>
    <visual>
      <origin rpy="0 0 0" xyz="0 0 0"/>
      <geometry>
        <mesh filename="./lz_gripper/meshes/ring_link2.STL"/>
      </geometry>
      <material name="">
        <color rgba="0.898039215686275 0.92156862745098 0.929411764705882 1"/>
      </material>
    </visual>
    <collision>
      <origin rpy="0 0 0" xyz="0 0 0"/>
      <geometry>
        <mesh filename="./lz_gripper/meshes/ring_link2.STL"/>
      </geometry>
    </collision>
  </link>
  <joint name="ring_joint2" type="revolute">
    <origin rpy="0 0 0" xyz="-0.045 0 -0.001"/>
    <parent link="ring_link1"/>
    <child link="ring_link2"/>
    <axis xyz="0 0 1"/>
    <limit effort="100" lower="0" upper="1.57" velocity="1"/>
  </joint>
  <link name="little_link1">
    <inertial>
      <origin rpy="0 0 0" xyz="0 0 0"/>
      <mass value="0"/>
      <inertia ixx="0" ixy="0" ixz="0" iyy="0" iyz="0" izz="0"/>
    </inertial>
    <visual>
      <origin rpy="0 0 0" xyz="0 0 0"/>
      <geometry>
        <mesh filename="./lz_gripper/meshes/little_link1.STL"/>
      </geometry>
      <material name="">
        <color rgba="1 1 1 1"/>
      </material>
    </visual>
    <collision>
      <origin rpy="0 0 0" xyz="0 0 0"/>
      <geometry>
        <mesh filename="./lz_gripper/meshes/little_link1.STL"/>
      </geometry>
    </collision>
  </link>
  <joint name="little_joint1" type="revolute">
    <origin rpy="0 1.501 0" xyz="-0.036007 0 -0.0094157"/>
    <parent link="base_link"/>
    <child link="little_link1"/>
    <axis xyz="0 0 1"/>
    <limit effort="100" lower="0" upper="1.57" velocity="1"/>
  </joint>
  <link name="little_link2">
    <inertial>
      <origin rpy="0 0 0" xyz="-0.0196680071986052 0.000581972212251745 -0.00789991313401341"/>
      <mass value="0.00784963356765954"/>
      <inertia ixx="2.81074629444425E-07" ixy="-1.75567896523501E-08" ixz="1.20217775074536E-11" iyy="1.53705622021842E-06" iyz="1.91083841216387E-12" izz="1.36360123319282E-06"/>
    </inertial>
    <visual>
      <origin rpy="0 0 0" xyz="0 0 0"/>
      <geometry>
        <mesh filename="./lz_gripper/meshes/little_link2.STL"/>
      </geometry>
      <material name="">
        <color rgba="0.898039215686275 0.92156862745098 0.929411764705882 1"/>
      </material>
    </visual>
    <collision>
      <origin rpy="0 0 0" xyz="0 0 0"/>
      <geometry>
        <mesh filename="./lz_gripper/meshes/little_link2.STL"/>
      </geometry>
    </collision>
  </link>
  <joint name="little_joint2" type="revolute">
    <origin rpy="0 0 0" xyz="-0.045 0 -0.001"/>
    <parent link="little_link1"/>
    <child link="little_link2"/>
    <axis xyz="0 0 1"/>
    <limit effort="100" lower="0" upper="1.57" velocity="1"/>
  </joint>
  <!-- Add fingertips links and joints -->
  <link name="index_tip">
    <visual>
      <origin rpy="0 -1.5708 0" xyz="0.004 -0.001 0"/>
      <geometry>
        <mesh filename="./lz_gripper/meshes/allegro_tip.obj" scale="0.8 0.6 0.8"/>
      </geometry>
      <material name="white">
        <color rgba=".9 .9 .9 1"/>
      </material>
    </visual>
  </link>
  <link name="little_tip">
    <visual>
      <origin rpy="0 -1.5708 0" xyz="0.004 -0.001 0"/>
      <geometry>
        <mesh filename="./lz_gripper/meshes/allegro_tip.obj" scale="0.8 0.6 0.8"/>
      </geometry>
      <material name="white">
        <color rgba=".9 .9 .9 1"/>
      </material>
    </visual>
  </link>
  <link name="middle_tip">
    <visual>
      <origin rpy="0 -1.5708 0" xyz="0.004 -0.001 0"/>
      <geometry>
        <mesh filename="./lz_gripper/meshes/allegro_tip.obj" scale="0.8 0.6 0.8"/>
      </geometry>
      <material name="white">
        <color rgba=".9 .9 .9 1"/>
      </material>
    </visual>
  </link>
  <link name="ring_tip">
    <visual>
      <origin rpy="0 -1.5708 0" xyz="0.004 -0.001 0"/>
      <geometry>
        <mesh filename="./lz_gripper/meshes/allegro_tip.obj" scale="0.8 0.6 0.8"/>
      </geometry>
      <material name="white">
        <color rgba=".9 .9 .9 1"/>
      </material>
    </visual>
  </link>
  <link name="thumb_tip">
    <visual>
      <origin rpy="0 -1.5708 0" xyz="0.004 0 0"/>
      <geometry>
        <mesh filename="./lz_gripper/meshes/allegro_thumb_tip.obj" scale="0.8 0.6 0.8"/>
      </geometry>
      <material name="white">
        <color rgba=".9 .9 .9 1"/>
      </material>
    </visual>
  </link>
  <joint name="index_tip_joint" type="fixed">
    <parent link="index_link2"/>
    <child link="index_tip"/>
    <origin rpy="0 0 0" xyz="-0.04 0 -0.008"/>
  </joint>
  <joint name="little_tip_joint" type="fixed">
    <parent link="little_link2"/>
    <child link="little_tip"/>
    <origin rpy="0 0 0" xyz="-0.04 0 -0.008"/>
  </joint>
  <joint name="middle_tip_joint" type="fixed">
    <parent link="middle_link2"/>
    <child link="middle_tip"/>
    <origin rpy="0 0 -1.5708" xyz="0 0.04 -0.008"/>
  </joint>
  <joint name="ring_tip_joint" type="fixed">
    <parent link="ring_link2"/>
    <child link="ring_tip"/>
    <origin rpy="0 0 0" xyz="-0.04 0 -0.008"/>
  </joint>
  <joint name="thumb_tip_joint" type="fixed">
    <parent link="thumb_link3"/>
    <child link="thumb_tip"/>
    <origin rpy="0 0 0" xyz="-0.04 0 0.008"/>
  </joint>
  <link name="world"/>
  <joint name="world_joint" type="fixed">
    <origin rpy="0 0 0" xyz="0 0 0"/>
    <parent link="world"/>
    <child link="base_link"/>
  </joint>
</robot>
